Workbook

Sheet ФЗП
A1: РАСЧЕТ к калькуляции
D3: =[1]параметры!D3 -> ввести с 1.01.2022г. | I3: ввести с 1.01.2017г. | L3: 2019 | M3: ввести с 1.01.2020г. | P3: 2021
A5: № п/п | B5: Статьи затрат | C5: Ед. изм. | D5: Сумма | I5: Сумма | J5: Сумма | L5: Сумма | M5: Сумма
J6: 2014
A7: 1 | B7: Материалы | C7: руб. | D7: =D8+D11+D14+D17+D20+D23+D26+D29+D32+D35 -> 0 | E7: =#REF!*#REF!+#REF!*#REF!+#REF!*#REF!+#REF!*#REF!+#REF!*#REF!+#REF!*#REF!+#REF!*#REF!+#REF!*#REF!+#REF!*#REF!+#REF!*#REF!-D7 -> #REF! | I7: 538.55 | J7: 546.53 | L7: 819.69 | M7: 832.8 | P7: =[2]расч!$D$7 -> 809.07 | Q7: =P7*1.035 -> 837.38745
A8: 1.1 | B8: =[1]параметры!B8 -> Эмаль ПФ-115, желтая, в/с | C8: руб | I8: 0 | J8: 0 | L8: 0 | M8: 0
B9: норма расхода | C9: кг
B10: цена за единицу | C10: руб
A11: 1.2 | B11: =[1]параметры!B11 -> Кисть малярная плоская КП60 | C11: руб | I11: 0 | J11: 0 | L11: 0 | M11: 0
B12: норма расхода | C12: шт
B13: цена за единицу | C13: руб
A14: 1.3 | B14: =[1]параметры!B14 -> Смазка графитная Ж | C14: руб | I14: 0 | J14: 0 | L14: 0 | M14: 0
B15: норма расхода | C15: т
B16: цена за единицу | C16: руб
A17: 1.4 | B17: =[1]параметры!B17 -> Растворитель Р-646 | C17: руб | I17: 0 | J17: 0 | L17: 0 | M17: 0
B18: норма расхода | C18: кг
B19: цена за единицу | C19: руб
A20: 1.5 | B20: =[1]параметры!B20 -> Паронит общего назначения (ПОН) толщина 1,0мм | C20: руб | I20: 0 | J20: 0 | L20: 0 | M20: 0
B21: норма расхода | C21: кг
B22: цена за единицу | C22: руб
A23: 1.6 | B23: =[1]параметры!B23 -> Паронит общего назначения ПОН 2,0 | C23: руб | I23: 0 | J23: 0 | L23: 0 | M23: 0
B24: норма расхода | C24: кг
B25: цена за единицу | C25: руб
A26: 1.17 | B26: =[1]параметры!B26 -> Ветошь (кг) | C26: руб | I26: 0 | J26: 0 | L26: 0 | M26: 0
B27: норма расхода | C27: =[1]параметры!C27 -> кг
B28: цена за единицу | C28: руб
A29: 1.18 | B29: =[1]параметры!B29 -> Набивка сальниковая АФТ 6х6 Набивки сальниковые асб. и неасбестовые) | C29: руб | I29: 0 | J29: 0 | L29: 0 | M29: 0
B30: норма расхода | C30: =[1]параметры!C30 -> кг
B31: цена за единицу | C31: руб
A32: 1.19 | B32: =[1]параметры!B32 -> Ведро оцинкованное 10л | C32: руб | I32: 0 | J32: 0 | L32: 0 | M32: 0
B33: норма расхода | C33: шт
B34: цена за единицу | C34: руб
A35: 1.20 | B35: =[1]параметры!B35 -> Эмаль ПФ-115, красная 1/С | C35: руб | I35: 0 | J35: 0 | L35: 0 | M35: 0
B36: норма расхода | C36: кг
B37: цена за единицу | C37: руб
A38: 1.21 | C38: руб | I38: 0 | J38: 0 | L38: 0 | M38: 0
B39: норма расхода
B40: цена за единицу | C40: руб
A41: 1.22 | C41: руб | I41: 0 | J41: 0 | L41: 0 | M41: 0
B42: норма расхода
...

Sheet Лист1
A1: № п/п | B1: Наименование статьи затрат | C1: Ед. измерения | D1: До реализации проекта | E1: После реализации проекта | F1: Эффект ("-" сокращение/"+" увеличение)
A2: 1. | B2: Капитальные вложения | C2: тыс.руб. | E2: =SUM(E3:E4) -> 0 | F2: =E2-D2 -> 0
F3: =E3-D3 -> 0
F4: =E4-D4 -> 0
A5: 2. | B5: Доходы, всего | D5: =D6+D9 -> -389.89031 | E5: =E6+E9 -> 0 | F5: =E5-D5 -> 389.89031
A6: 2.1. | B6: Потеря выручки за время простоя котельной в отопительный сезон | C6: тыс. руб. | D6: =-D8*D9*D10*D7/1000 -> -395.89031 | F6: =E6-D6 -> 395.89031
B7: Среднее количество порывов за отопительный сезон | C7: шт. | D7: 4 | F7: -4
A8: 2.1.1. | B8: Время простоя котельной во время порыва | C8: ч. | D8: 4 | F8: =E8-D8 -> -4
A9: 2.1.2. | B9: Производительность котельной | C9: Гкал/ч. | D9: 6 | F9: =E9-D9 -> -6
A10: 2.1.3. | B10: Средний тариф по теплоснабжению | C10: руб./Гкал. | D10: 4123.8574 | F10: =E10-D10 -> -4123.8574
A11: 3. | B11: Расходы, всего | C11: тыс. руб. | D11: =D12 -> 1268.9801 | E11: =E12+E15+E18+E19 -> 0 | F11: =D11-E11 -> 1268.9801
A12: 3.1. | B12: Расходы на восстановление теплоснабжения в отопительный сезон | C12: тыс. руб. | D12: =D15*D18*D21*D13/1000+D16*D13*D19*D22/1000 -> 1268.9801 | F12: =D12-E12 -> 1268.9801
A13: 3.2. | B13: Среднее количество порывов за отопительный сезон | C13: шт. | D13: 4 | F13: -4
A14: 3.2. | B14: Средний объем ТС
A15: 3.2.1. | B15: по нефтяным котельным | C15: м3 | D15: 32.68 | F15: =E15-D15 -> -32.68
A16: 3.2.2. | B16: по газ.котельным | C16: м3 | D16: 165.05 | F16: =E16-D16 -> -165.05
A17: 3.3. | B17: Расход топлива на подогрев теплоносителя
A18: 3.3.1. | B18: На нефтяных котельных | C18: тн/м3 | D18: 0.2 | F18: =E18-D18 -> -0.2
A19: 3.3.2. | B19: На газовых котельных | C19: м3 газа/м3 | D19: 12 | F19: =E19-D19 -> -12
A20: 3.4. | B20: Цена на топливо
A21: 3.4.1. | B21: Цена на нефть | C21: руб./тн | D21: 46635.196
A22: 3.4.2. | B22: Цена на газ | C22: руб./м3 | D22: 6.2795983
A23: 4. | B23: Финансовый результат, всего | C23: тыс .руб. | D23: =D5-D11 -> -1658.8704 | E23: =E5+E2+E11 -> 0 | F23: =E23-D23 -> 1658.8704
C31: - уточнить данные!!!

Sheet Лист4
A1: № п./п. | B1: Наименование | C1: Едининца измерения | D1: Тепловизионный контроль | E1: Приложение с автоматической обработкой данных
A2: 1. | B2: Затраты на тепловизионный контроль
A3: 45292 | B3: Количество ПС 35-110 кВ в ООО «Удмуртэнергонефть» | C3: шт. | D3: 48
A4: 45323 | B4: Зарплата ведущего инженера РЗА за 1 ч. | C4: руб. | D4: 552.29
A5: 45352 | B5: Время проведения тепловизонного контроля одной ПС 35-110 кВ | C5: ч. | D5: 8
A6: 45383 | B6: Среднее количество обходов для выполнения тепловизионного контроля одной подстанции в год | C6: кол-во | D6: 2
A7: 45413 | B7: Затраты на обход ПС 35-110 кВ в ООО «Удмуртэнергонефть» за год | C7: тыс. руб. | D7: 424.1
A8: 45444 | B8: Среднее расстояние между ООО «Удмуртэнергонефть» и ПС 35-110 кВ (в обе стороны) | C8: км | D8: 139,2‬
A9: 45474 | B9: Стоимость за 1 машино-час | C9: руб. | D9: 241.87
A10: 45505 | B10: Стоимость за 1 км. | C10: руб. | D10: 43252
A11: 45536 | B11: Общие затраты на транспорт | C11: тыс. руб. | D11: 134.1
A12: 45566 | B12: Стоимость тепловизора HIKMICRO G40 (5 шт.) | C12: тыс. руб./5 шт. | D12: 4 999,9
A13: 45597 | B13: Затраты на тепловизионный контроль, итого | C13: тыс. руб. | D13: 5 558,1 | E13: -
A14: 2. | B14: Затраты на установку приложения автомат. обработки данных
A15: 45293 | B15: IP-камера DH-IPC-HFW3841EP-AS-0280B | C15: тыс. руб./4 шт. | D15: - | E15: 79.1
A16: 2.2. | B16: Количество ПС 35-110 кВ в ООО «Удмуртэнергонефть» | C16: шт. | D16: - | E16: 48
A17: 2.3. | B17: Затраты на установку приложения автомат. обработки данных, итого | C17: тыс. руб. | D17: - | E17: 114.4
A18: 3. | B18: Финансовый результат, всего | C18: тыс. руб. | E18: 1756.7

Sheet расч 
A1: РАСЧЕТ к калькуляции
E2: =[5]прайс_УПГ_2010!$H$12 -> 1.46
D3: ввести с 1.01.2020г. | I3: ввести с 1.01.2017г.
L4: 2019
A5: № п/п | B5: Статьи затрат | C5: Ед. изм. | D5: Сумма | I5: Сумма | J5: ввести с 1.01.2014г. | L5: Сумма
A7: 1 | B7: Материалы | C7: руб. | D7: =D8+D11+D14+D17 -> 0 | I7: 19.95 | J7: Сумма | L7: 23.74
A8: 1.1 | B8: Ветошь | C8: руб | I8: 16.67 | L8: 20.72
B9: норма расхода | C9: кг. | I9: 0.67 | J9: 20.06 | L9: 0.67
B10: цена за единицу | C10: руб | I10: 24.880412 | J10: 16.78 | L10: 30.93
A11: 1.2 | B11: Смазка Литол-24 (9кг) | C11: руб | I11: 1.27 | J11: 0.67460005 | L11: 2.12
B12: норма расхода | C12: шт. | I12: 0.002 | J12: 24.880412 | L12: 0.002
B13: цена за единицу | C13: руб | I13: 633.01178 | J13: 1.27 | L13: 1059.32
A14: 1.3 | B14: Набивка сальниковая АФТ 6х6 | C14: руб | I14: 2.01 | J14: 0.002 | L14: 0.9
B15: норма расхода | C15: кг. | I15: 0.002 | J15: 633.01178 | L15: 0.002
B16: цена за единицу | C16: руб | I16: 1003.248 | J16: 2.01 | L16: 449.81
J17: 0.002
J18: 1003.248
A20: 1.5 | C20: руб
B21: норма расхода | C21: кг. | D21: 0.47 | I21: 0.47 | L21: 0.47
B22: цена за единицу | C22: руб | D22: =[6]материалы!$E$112 -> 0 | I22: 0 | L22: 0
A23: 1.6 | C23: руб | J23: 0.47
B24: норма расхода | C24: л. | D24: 0.96 | I24: 0.96 | J24: 0 | L24: 0.96
B25: цена за единицу | C25: руб | D25: =[6]материалы!$E$117 -> 1000 | I25: 1000 | J25: 960 | L25: 1000
A26: 1.7 | C26: руб | D26: =ROUND(D27*D28,2) -> 0 | I26: 0 | J26: 0.96 | L26: 0
B27: норма расхода | J27: 1000
B28: цена за единицу | C28: руб | J28: 0
A29: 1.8 | C29: руб | D29: =ROUND(D30*D31,2) -> 0 | I29: 0 | L29: 0
B30: норма расхода
B31: цена за единицу | C31: руб | J31: 0
A32: 1.9 | C32: руб | D32: =ROUND(D33*D34,2) -> 0 | I32: 0 | L32: 0
B33: норма расхода
B34: цена за единицу | C34: руб | J34: 0
A35: 1.10 | C35: руб | D35: =ROUND(D36*D37,2) -> 0 | I35: 0 | L35: 0
B36: норма расхода
B37: цена за единицу | C37: руб | J37: 0
A38: 1.11 | C38: руб | D38: =ROUND(D39*D40,2) -> 0 | I38: 0 | L38: 0
B39: норма расхода
B40: цена за единицу | C40: руб | J40: 0
A41: 1.12 | C41: руб | D41: =ROUND(D42*D43,2) -> 0 | I41: 0 | L41: 0
B42: норма расхода
...

Sheet Расчет_окупаемости
A1: Расчет приведенной стоимости, за 5 лет
A2: Год | B2: Затраты на приобретение ОС (инвестиции) | C2: Снижение затрат | D2: Сальдо | E2: ="КД (r="&TEXT($L$3,"0,00")&")" -> КД (r=0,20) | F2: Сальдо с учетом КД | G2: NPV | H2: NPV | L2: 0.13
A3: 1 | B3: =Лист4!E17 -> 114.4 | C3: =Лист4!E18 -> 1756.7 | D3: =C3-B3 -> 1642.3 | E3: =1/((1+$L$3)^A3) -> 0.83333333 | F3: =E3*D3 -> 1368.5833 | G3: =F3 -> 1368.5833 | H3: 3740.53 | I3: =IF(G3>0,1,0) -> 1 | L3: 0.2 | N3: 0.13
A4: 2 | B4: 0 | C4: =C3*(1+$L$2) -> 1985.071 | D4: =C4-B4 -> 1985.071 | E4: =1/((1+$L$3)^A4) -> 0.69444444 | F4: =E4*D4 -> 1378.5215 | G4: =G3+F4 -> 2747.1049 | H4: =H3+3740.53 -> 7481.06 | I4: =IF(G4>0,1,0) -> 1 | N4: 0.2
A5: 3 | B5: =B4*1.1 -> 0 | C5: =C4*(1+$L$2) -> 2243.1302 | D5: =C5-B5 -> 2243.1302 | E5: =1/((1+$L$3)^A5) -> 0.5787037 | F5: =E5*D5 -> 1298.1078 | G5: =G4+F5 -> 4045.2126 | H5: =H4+3740.53 -> 11221.59 | I5: =IF(G5>0,1,0) -> 1
A6: 4 | B6: =B5*1.1 -> 0 | C6: =C5*(1+$L$2) -> 2534.7372 | D6: =C6-B6 -> 2534.7372 | E6: =1/((1+$L$3)^A6) -> 0.48225309 | F6: =E6*D6 -> 1222.3848 | G6: =G5+F6 -> 5267.5975 | H6: =H5+3740.53 -> 14962.12 | I6: =IF(G6>0,1,0) -> 1
A7: 5 | B7: =B6*1.1 -> 0 | C7: =C6*(1+$L$2) -> 2864.253 | D7: =C7-B7 -> 2864.253 | E7: =1/((1+$L$3)^A7) -> 0.40187757 | F7: =E7*D7 -> 1151.079 | G7: =G6+F7 -> 6418.6765 | H7: =H6+3740.53 -> 18702.65 | I7: =IF(G7>0,1,0) -> 1
A8: 6 | B8: =B7*1.1 -> 0 | C8: =C7*(1+$L$2) -> 3236.6059 | D8: =C8-B8 -> 3236.6059 | E8: =1/((1+$L$3)^A8) -> 0.33489798 | F8: =E8*D8 -> 1083.9328 | G8: =G7+F8 -> 7502.6092 | H8: =H7+3740.53 -> 22443.18 | I8: =IF(G8>0,1,0) -> 1
A9: 7 | B9: =B8*1.1 -> 0 | C9: =C8*(1+$L$2) -> 3657.3646 | D9: =C9-B9 -> 3657.3646 | E9: =1/((1+$L$3)^A9) -> 0.27908165 | F9: =E9*D9 -> 1020.7033 | G9: =G8+F9 -> 8523.3126 | H9: =H8+3740.53 -> 26183.71 | I9: =IF(G9>0,1,0) -> 1
A10: 8 | B10: =B9*1.1 -> 0 | C10: =C9*(1+$L$2) -> 4132.822 | D10: =C10-B10 -> 4132.822 | E10: =1/((1+$L$3)^A10) -> 0.23256804 | F10: =E10*D10 -> 961.16232 | G10: =G9+F10 -> 9484.4749 | H10: =H9+3740.53 -> 29924.24 | I10: =IF(G10>0,1,0) -> 1
A11: 9 | B11: =B10*1.1 -> 0 | C11: =C10*(1+$L$2) -> 4670.0889 | D11: =C11-B11 -> 4670.0889 | E11: =1/((1+$L$3)^A11) -> 0.1938067 | F11: =E11*D11 -> 905.09452 | G11: =G10+F11 -> 10389.569 | H11: =H10+3740.53 -> 33664.77 | I11: =IF(G11>0,1,0) -> 1
A12: 10 | B12: =B11*1.1 -> 0 | C12: =C11*(1+$L$2) -> 5277.2005 | D12: =C12-B12 -> 5277.2005 | E12: =1/((1+$L$3)^A12) -> 0.16150558 | F12: =E12*D12 -> 852.29734 | G12: =G11+F12 -> 11241.867 | H12: =H11+3740.53 -> 37405.3 | I12: =IF(G12>0,1,0) -> 1
A13: 11 | B13: =B12*1.1 -> 0 | C13: =C12*(1+$L$2) -> 5963.2365 | D13: =C13-B13 -> 5963.2365 | E13: =1/((1+$L$3)^A13) -> 0.13458799 | F13: =E13*D13 -> 802.57999 | G13: =G12+F13 -> 12044.447 | I13: =IF(G13>0,1,0) -> 1
A14: 12 | B14: =B13*1.1 -> 0 | C14: =C13*(1+$L$2) -> 6738.4573 | D14: =C14-B14 -> 6738.4573 | E14: =1/((1+$L$3)^A14) -> 0.11215665 | F14: =E14*D14 -> 755.76283 | G14: =G13+F14 -> 12800.21 | I14: =IF(G14>0,1,0) -> 1
A15: 13 | B15: =B14*1.1 -> 0 | C15: =C14*(1+$L$2) -> 7614.4567 | D15: =C15-B15 -> 7614.4567 | E15: =1/((1+$L$3)^A15) -> 0.093463879 | F15: =E15*D15 -> 711.67666 | G15: =G14+F15 -> 13511.886 | I15: =IF(G15>0,1,0) -> 1
A16: 14 | B16: =B15*1.1 -> 0 | C16: =C15*(1+$L$2) -> 8604.3361 | D16: =C16-B16 -> 8604.3361 | E16: =1/((1+$L$3)^A16) -> 0.077886566 | F16: =E16*D16 -> 670.16219 | G16: =G15+F16 -> 14182.048 | I16: =IF(G16>0,1,0) -> 1
A17: 15 | B17: =B16*1.1 -> 0 | C17: =C16*(1+$L$2) -> 9722.8998 | D17: =C17-B17 -> 9722.8998 | E17: =1/((1+$L$3)^A17) -> 0.064905472 | F17: =E17*D17 -> 631.0694 | G17: =G16+F17 -> 14813.118 | I17: =IF(G17>0,1,0) -> 1
A18: 16 | B18: =B17*1.1 -> 0 | C18: =C17*(1+$L$2) -> 10986.877 | D18: =C18-B18 -> 10986.877 | E18: =1/((1+$L$3)^A18) -> 0.054087893 | F18: =E18*D18 -> 594.25701 | G18: =G17+F18 -> 15407.375 | I18: =IF(G18>0,1,0) -> 1
A19: 17 | B19: =B18*1.1 -> 0 | C19: =C18*(1+$L$2) -> 12415.171 | D19: =C19-B19 -> 12415.171 | E19: =1/((1+$L$3)^A19) -> 0.045073244 | F19: =E19*D19 -> 559.59202 | G19: =G18+F19 -> 15966.967 | I19: =IF(G19>0,1,0) -> 1
A20: 18 | B20: =B19*1.1 -> 0 | C20: =C19*(1+$L$2) -> 14029.143 | D20: =C20-B20 -> 14029.143 | E20: =1/((1+$L$3)^A20) -> 0.037561037 | F20: =E20*D20 -> 526.94915 | G20: =G19+F20 -> 16493.916 | I20: =IF(G20>0,1,0) -> 1
A21: 19 | B21: =B20*1.1 -> 0 | C21: =C20*(1+$L$2) -> 15852.932 | D21: =C21-B21 -> 15852.932 | E21: =1/((1+$L$3)^A21) -> 0.031300864 | F21: =E21*D21 -> 496.21045 | G21: =G20+F21 -> 16990.126 | I21: =IF(G21>0,1,0) -> 1
A22: 20 | B22: =B21*1.1 -> 0 | C22: =C21*(1+$L$2) -> 17913.813 | D22: =C22-B22 -> 17913.813 | E22: =1/((1+$L$3)^A22) -> 0.026084053 | F22: =E22*D22 -> 467.26484 | G22: =G21+F22 -> 17457.391 | I22: =IF(G22>0,1,0) -> 1
I23: =MATCH(1,I3:I22,0) -> 1
A24: Расчет приведенной стоимости за первый год помесячно:
A25: Месяц | B25: Расходы | C25: Доходы | D25: Сальдо | E25: ="КД (r="&TEXT($L$2,"0,00")&")" -> КД (r=0,13) | F25: Сальдо с учетом КД | G25: NPV
A26: 1 | B26: =B3 -> 114.4 | C26: =($C$3)/12-H26 -> 146.39167 | D26: =C26-B26 -> 31.991667 | E26: =1/((1+$L$3)^(A26/12)) -> 0.98492138 | F26: =E26*D26 -> 31.509276 | G26: =F26 -> 31.509276 | I26: =IF(G26>0,1,0) -> 1
A27: 2 | C27: =($C$3)/12-H27 -> 146.39167 | D27: =C27-B27 -> 146.39167 | E27: =1/((1+$L$3)^(A27/12)) -> 0.97007012 | F27: =E27*D27 -> 142.01018 | G27: =G26+F27 -> 173.51946 | I27: =IF(G27>0,1,0) -> 1
A28: 3 | C28: =($C$3)/12-H28 -> 146.39167 | D28: =C28-B28 -> 146.39167 | E28: =1/((1+$L$3)^(A28/12)) -> 0.95544279 | F28: =E28*D28 -> 139.86886 | G28: =G27+F28 -> 313.38832 | I28: =IF(G28>0,1,0) -> 1
A29: 4 | C29: =($C$3)/12-H29 -> 146.39167 | D29: =C29-B29 -> 146.39167 | E29: =1/((1+$L$3)^(A29/12)) -> 0.94103603 | F29: =E29*D29 -> 137.75983 | G29: =G28+F29 -> 451.14815 | I29: =IF(G29>0,1,0) -> 1
A30: 5 | C30: =($C$3)/12-H30 -> 146.39167 | D30: =C30-B30 -> 146.39167 | E30: =1/((1+$L$3)^(A30/12)) -> 0.9268465 | F30: =E30*D30 -> 135.6826 | G30: =G29+F30 -> 586.83076 | I30: =IF(G30>0,1,0) -> 1
A31: 6 | C31: =($C$3)/12-H31 -> 146.39167 | D31: =C31-B31 -> 146.39167 | E31: =1/((1+$L$3)^(A31/12)) -> 0.91287093 | F31: =E31*D31 -> 133.6367 | G31: =G30+F31 -> 720.46745 | I31: =IF(G31>0,1,0) -> 1
A32: 7 | C32: =($C$3)/12-H32 -> 146.39167 | D32: =C32-B32 -> 146.39167 | E32: =1/((1+$L$3)^(A32/12)) -> 0.89910609 | F32: =E32*D32 -> 131.62164 | G32: =G31+F32 -> 852.08909 | I32: =IF(G32>0,1,0) -> 1
A33: 8 | C33: =($C$3)/12-H33 -> 146.39167 | D33: =C33-B33 -> 146.39167 | E33: =1/((1+$L$3)^(A33/12)) -> 0.88554881 | F33: =E33*D33 -> 129.63697 | G33: =G32+F33 -> 981.72606 | I33: =IF(G33>0,1,0) -> 1
A34: 9 | C34: =($C$3)/12-H34 -> 146.39167 | D34: =C34-B34 -> 146.39167 | E34: =1/((1+$L$3)^(A34/12)) -> 0.87219595 | F34: =E34*D34 -> 127.68222 | G34: =G33+F34 -> 1109.4083 | I34: =IF(G34>0,1,0) -> 1
A35: 10 | C35: =($C$3)/12-H35 -> 146.39167 | D35: =C35-B35 -> 146.39167 | E35: =1/((1+$L$3)^(A35/12)) -> 0.85904443 | F35: =E35*D35 -> 125.75695 | G35: =G34+F35 -> 1235.1652 | I35: =IF(G35>0,1,0) -> 1
A36: 11 | C36: =($C$3)/12-H36 -> 146.39167 | D36: =C36-B36 -> 146.39167 | E36: =1/((1+$L$3)^(A36/12)) -> 0.84609123 | F36: =E36*D36 -> 123.8607 | G36: =G35+F36 -> 1359.0259 | I36: =IF(G36>0,1,0) -> 1
A37: 12 | C37: =($C$3)/12-H37 -> 146.39167 | D37: =C37-B37 -> 146.39167 | E37: =1/((1+$L$3)^(A37/12)) -> 0.83333333 | F37: =E37*D37 -> 121.99306 | G37: =G36+F37 -> 1481.019 | I37: =IF(G37>0,1,0) -> 1
I38: =MATCH(1,I26:I37,0) -> 1
